Workbook

Sheet dummy
A1: Order ID | B1: Order Date | C1: Ship Date | D1: Customer Name | E1: Segment | F1: Region | G1: Category | H1: Sub-Category | I1: Product Name | J1: Sales | K1: Quantity | L1: Discount | M1: Profit
A2: ORD-10001 | B2: 45177 | C2: 45178 | D2: Traci Sanchez | E2: Consumer | F2: North | G2: Office Supplies | H2: Binders | I2: Happy Binders | J2: 3720.67 | K2: 4 | L2: 0.05 | M2: -458.59
A3: ORD-10002 | B3: 46086 | C3: 46087 | D3: Norman Jordan | E3: Consumer | F3: South | G3: Office Supplies | H3: Paper | I3: Fight Paper | J3: 197.5 | K3: 4 | L3: 0.05 | M3: 15.39
A4: ORD-10003 | B4: 45235 | C4: 45244 | D4: Thomas Scott | E4: Consumer | F4: South | G4: Office Supplies | H4: Storage | I4: Process Storage | J4: 2126.62 | K4: 8 | L4: 0.2 | M4: -99.94
A5: ORD-10004 | B5: 45523 | C5: 45529 | D5: Samuel Diaz | E5: Corporate | F5: North | G5: Office Supplies | H5: Paper | I5: Prepare Paper | J5: 1425.46 | K5: 4 | L5: 0.1 | M5: -204.96
A6: ORD-10005 | B6: 45860 | C6: 45870 | D6: Tiffany Ruiz | E6: Consumer | F6: West | G6: Technology | H6: Accessories | I6: Coach Accessories | J6: 1359.38 | K6: 1 | M6: 71.62
A7: ORD-10006 | B7: 45335 | C7: 45340 | D7: Stephanie Rodriguez | E7: Home Office | F7: North | G7: Furniture | H7: Bookcases | I7: Task Bookcases | J7: 4155.55 | K7: 10 | L7: 0.1 | M7: 488.46
A8: ORD-10007 | B8: 46018 | C8: 46022 | D8: Barbara Mora | E8: Corporate | F8: East | G8: Furniture | H8: Bookcases | I8: Available Bookcases | J8: 3876.69 | K8: 2 | L8: 0.05 | M8: 1072.16
A9: ORD-10008 | B9: 45288 | C9: 45294 | D9: Gloria Brown | E9: Home Office | F9: North | G9: Technology | H9: Laptops | I9: Beautiful Laptops | J9: 855.14 | K9: 6 | L9: 0.05 | M9: 144.17
A10: ORD-10009 | B10: 45374 | C10: 45377 | D10: Stephen Adkins | E10: Corporate | F10: South | G10: Office Supplies | H10: Storage | I10: Purpose Storage | J10: 2693.99 | K10: 4 | L10: 0.05 | M10: 146.13
A11: ORD-10010 | B11: 46080 | C11: 46081 | D11: Rachel Mathews | E11: Consumer | F11: South | G11: Office Supplies | H11: Paper | I11: Last Paper | J11: 1183.79 | K11: 1 | L11: 0.1 | M11: 24.43
A12: ORD-10011 | B12: 45524 | C12: 45530 | D12: Jacqueline Johnson | E12: Home Office | F12: West | G12: Office Supplies | H12: Storage | I12: Prepare Storage | J12: 1102.5 | K12: 8 | L12: 0.15 | M12: 315.95
A13: ORD-10012 | B13: 45574 | C13: 45577 | D13: Kevin Anderson | E13: Home Office | F13: West | G13: Furniture | H13: Tables | I13: Live Tables | J13: 1270.81 | K13: 9 | L13: 0.2 | M13: -70.52
A14: ORD-10013 | B14: 45524 | C14: 45530 | D14: Kenneth Sullivan | E14: Consumer | F14: North | G14: Office Supplies | H14: Paper | I14: Example Paper | J14: 1135.64 | K14: 3 | L14: 0.2 | M14: 81.12
A15: ORD-10014 | B15: 45338 | C15: 45341 | D15: John Bates | E15: Corporate | F15: West | G15: Furniture | H15: Bookcases | I15: Individual Bookcases | J15: 3970.79 | K15: 7 | L15: 0.2 | M15: -655.42
A16: ORD-10015 | B16: 45214 | C16: 45223 | D16: Patrick Horn | E16: Home Office | F16: East | G16: Office Supplies | H16: Paper | I16: Tough Paper | J16: 4310.86 | K16: 1 | M16: 846.64
A17: ORD-10016 | B17: 45297 | C17: 45299 | D17: Danny Clark | E17: Home Office | F17: East | G17: Office Supplies | H17: Paper | I17: Cover Paper | J17: 1502.83 | K17: 3 | L17: 0.15 | M17: -297.88
A18: ORD-10017 | B18: 45233 | C18: 45242 | D18: Thomas Olson | E18: Consumer | F18: South | G18: Office Supplies | H18: Binders | I18: Thousand Binders | J18: 4567.51 | K18: 5 | M18: 361.81
A19: ORD-10018 | B19: 45669 | C19: 45678 | D19: Jeffrey Levy | E19: Corporate | F19: North | G19: Technology | H19: Phones | I19: Ahead Phones | J19: 4769.82 | K19: 9 | L19: 0 | M19: 617.31
A20: ORD-10019 | B20: 45262 | C20: 45267 | D20: James Hamilton | E20: Consumer | F20: West | G20: Furniture | H20: Tables | I20: Build Tables | J20: 1235.29 | K20: 4 | L20: 0.2 | M20: 396.31
A21: ORD-10020 | B21: 45662 | C21: 45665 | D21: Joshua Smith | E21: Home Office | F21: West | G21: Furniture | H21: Bookcases | I21: Cell Bookcases | J21: 685.54 | K21: 8 | L21: 0.2 | M21: -74.85
A22: ORD-10021 | B22: 46154 | C22: 46158 | D22: Lorraine Ruiz | E22: Corporate | F22: West | G22: Furniture | H22: Bookcases | I22: Suddenly Bookcases | J22: 3579.1 | K22: 7 | M22: 563.47
A23: ORD-10022 | B23: 45989 | C23: 45993 | D23: Terri Miller | E23: Home Office | F23: South | G23: Furniture | H23: Chairs | I23: Forget Chairs | J23: 366.93 | K23: 1 | L23: 0.2 | M23: 38.4
A24: ORD-10023 | B24: 45383 | C24: 45384 | D24: Stacey Lewis | E24: Consumer | F24: East | G24: Furniture | H24: Chairs | I24: Than Chairs | J24: 1183.26 | K24: 1 | L24: 0.1 | M24: -190.54
A25: ORD-10024 | B25: 45796 | C25: 45800 | D25: Amanda Roberts | E25: Corporate | F25: West | G25: Office Supplies | H25: Paper | I25: Culture Paper | J25: 2719.21 | K25: 10 | L25: 0.2 | M25: 163.07
A26: ORD-10025 | B26: 45564 | C26: 45566 | D26: William Fernandez | E26: Home Office | F26: North | G26: Furniture | H26: Chairs | I26: Cultural Chairs | J26: 3311.96 | K26: 6 | L26: 0.15 | M26: 86.46
A27: ORD-10026 | B27: 45647 | C27: 45649 | D27: Nicholas Taylor | E27: Consumer | F27: West | G27: Office Supplies | H27: Storage | I27: Make Storage | J27: 350.03 | K27: 6 | L27: 0 | M27: -22.14
A28: ORD-10027 | B28: 45441 | C28: 45444 | D28: Amanda Roy | E28: Home Office | F28: North | G28: Furniture | H28: Tables | I28: His Tables | J28: 1428.8 | K28: 4 | L28: 0 | M28: 62.47
A29: ORD-10028 | B29: 45683 | C29: 45692 | D29: Charles Moore | E29: Corporate | F29: West | G29: Furniture | H29: Bookcases | I29: Yeah Bookcases | J29: 4188.34 | K29: 2 | L29: 0.05 | M29: -454.56
A30: ORD-10029 | B30: 45352 | C30: 45353 | D30: Linda Wells | E30: Corporate | F30: East | G30: Furniture | H30: Tables | I30: Important Tables | J30: 864.95 | K30: 1 | L30: 0.15 | M30: -46.83
A31: ORD-10030 | B31: 45088 | C31: 45097 | D31: Daniel King | E31: Consumer | F31: North | G31: Technology | H31: Laptops | I31: Themselves Laptops | J31: 3326.26 | K31: 8 | L31: 0.05 | M31: -317.84
A32: ORD-10031 | B32: 46145 | C32: 46154 | D32: Ricardo Ramirez | E32: Corporate | F32: South | G32: Office Supplies | H32: Storage | I32: Growth Storage | J32: 351.74 | K32: 6 | L32: 0 | M32: -60.65
A33: ORD-10032 | B33: 45961 | C33: 45963 | D33: Erika Ellis | E33: Consumer | F33: West | G33: Furniture | H33: Bookcases | I33: One Bookcases | J33: 4264.15 | K33: 2 | L33: 0.2 | M33: -693.44
A34: ORD-10033 | B34: 46008 | C34: 46012 | D34: Pamela Norman | E34: Home Office | F34: East | G34: Furniture | H34: Bookcases | I34: Wait Bookcases | J34: 2915.65 | K34: 1 | L34: 0.2 | M34: -451.66
... A37: ORD-10036 | B37: 45724 | C37: 45726 | D37: Katelyn Williams | E37: Home Office | F37: East | G37: Furniture | H37: Tables | I37: Son Tables | J37: 4402.39 | K37: 6 | L37: 0.1 | M37: -498.52
A38: ORD-10037 | B38: 07-11-2023 | C38: 45246 | D38: Shannon Wagner | E38: Consumer | F38: South | G38: Office Supplies | H38: Storage | I38: With Storage | J38: 88.72 | K38: 9 | L38: 0.1 | M38: 27.72
A39: ORD-10038 | B39: 45815 | C39: 45817 | D39: Kelli Johnson | E39: Consumer | F39: East | G39: Technology | H39: Phones | I39: This Phones | J39: 3724.96 | K39: 3 | L39: 0.1 | M39: -167.75
A40: ORD-10039 | B40: 45087 | C40: 45092 | D40: Rebecca Blake | E40: Corporate | F40: East | G40: Furniture | H40: Bookcases | I40: Throughout Bookcases | J40: 2551.77 | K40: 5 | L40: 0 | M40: -380.82
A41: ORD-10040 | B41: 46089 | C41: 46095 | D41: Brian Gallagher | E41: Home Office | F41: West | G41: Furniture | H41: Chairs | I41: According Chairs | J41: 3867.04 | K41: 5 | L41: 0.05 | M41: 803.1
A42: ORD-10041 | B42: 45846 | C42: 45848 | D42: Melissa Burgess | E42: Corporate | F42: South | G42: Office Supplies | H42: Binders | I42: Three Binders | J42: 422.46 | K42: 3 | L42: 0.2 | M42: -76.12
...

Sheet data cleaning
A1: Order ID | B1: Order Date | C1: Ship Date | D1: Customer Name3 | E1: Customer Name2 | F1: Segment | G1: Segment2 | H1: Region | I1: Region2 | J1: Category | K1: Category2 | L1: Sub-Category | M1: Sub-Category2 | N1: Product Name | O1: Product Name3 | P1: Product Name2 | Q1: Sales | R1: Quantity | S1: Discount | T1: Profit
A2: ORD-10001 | B2: 45177 | C2: 45178 | D2: =TRIM('data cleaning'!$E2) -> Traci Sanchez | E2: Traci Sanchez | F2: =TRIM('data cleaning'!$G2) -> Consumer | G2: Consumer | H2: =TRIM('data cleaning'!$I2) -> North | I2: North | J2: =TRIM('data cleaning'!$K2) -> Office Supplies | K2: Office Supplies | L2: =TRIM('data cleaning'!$M2) -> Binders | M2: Binders | N2: =PROPER('data cleaning'!$O2) -> Happy Binders | O2: =TRIM('data cleaning'!$P2) -> Happy Binders | P2: Happy Binders | Q2: 3720.67 | R2: 4 | S2: 0.05 | T2: -458.59
A3: ORD-10002 | B3: 46086 | C3: 46087 | D3: =TRIM('data cleaning'!$E3) -> Norman Jordan | E3: Norman Jordan | F3: =TRIM('data cleaning'!$G3) -> Consumer | G3: Consumer | H3: =TRIM('data cleaning'!$I3) -> South | I3: South | J3: =TRIM('data cleaning'!$K3) -> Office Supplies | K3: Office Supplies | L3: =TRIM('data cleaning'!$M3) -> Paper | M3: Paper | N3: =PROPER('data cleaning'!$O3) -> Fight Paper | O3: =TRIM('data cleaning'!$P3) -> Fight Paper | P3: Fight Paper | Q3: 197.5 | R3: 4 | S3: 0.05 | T3: 15.39
A4: ORD-10003 | B4: 45235 | C4: 45244 | D4: =TRIM('data cleaning'!$E4) -> Thomas Scott | E4: Thomas Scott | F4: =TRIM('data cleaning'!$G4) -> Consumer | G4: Consumer | H4: =TRIM('data cleaning'!$I4) -> South | I4: South | J4: =TRIM('data cleaning'!$K4) -> Office Supplies | K4: Office Supplies | L4: =TRIM('data cleaning'!$M4) -> Storage | M4: Storage | N4: =PROPER('data cleaning'!$O4) -> Process Storage | O4: =TRIM('data cleaning'!$P4) -> Process Storage | P4: Process Storage | Q4: 2126.62 | R4: 8 | S4: 0.2 | T4: -99.94
A5: ORD-10004 | B5: 45523 | C5: 45529 | D5: =TRIM('data cleaning'!$E5) -> Samuel Diaz | E5: Samuel Diaz | F5: =TRIM('data cleaning'!$G5) -> Corporate | G5: Corporate | H5: =TRIM('data cleaning'!$I5) -> North | I5: North | J5: =TRIM('data cleaning'!$K5) -> Office Supplies | K5: Office Supplies | L5: =TRIM('data cleaning'!$M5) -> Paper | M5: Paper | N5: =PROPER('data cleaning'!$O5) -> Prepare Paper | O5: =TRIM('data cleaning'!$P5) -> Prepare Paper | P5: Prepare Paper | Q5: 1425.46 | R5: 4 | S5: 0.1 | T5: -204.96
A6: ORD-10005 | B6: 45860 | C6: 45870 | D6: =TRIM('data cleaning'!$E6) -> Tiffany Ruiz | E6: Tiffany Ruiz | F6: =TRIM('data cleaning'!$G6) -> Consumer | G6: Consumer | H6: =TRIM('data cleaning'!$I6) -> West | I6: West | J6: =TRIM('data cleaning'!$K6) -> Technology | K6: Technology | L6: =TRIM('data cleaning'!$M6) -> Accessories | M6: Accessories | N6: =PROPER('data cleaning'!$O6) -> Coach Accessories | O6: =TRIM('data cleaning'!$P6) -> Coach Accessories | P6: Coach Accessories | Q6: 1359.38 | R6: 1 | T6: 71.62
A7: ORD-10006 | B7: 45335 | C7: 45340 | D7: =TRIM('data cleaning'!$E7) -> Stephanie Rodriguez | E7: Stephanie Rodriguez | F7: =TRIM('data cleaning'!$G7) -> Home Office | G7: Home Office | H7: =TRIM('data cleaning'!$I7) -> North | I7: North | J7: =TRIM('data cleaning'!$K7) -> Furniture | K7: Furniture | L7: =TRIM('data cleaning'!$M7) -> Bookcases | M7: Bookcases | N7: =PROPER('data cleaning'!$O7) -> Task Bookcases | O7: =TRIM('data cleaning'!$P7) -> Task Bookcases | P7: Task Bookcases | Q7: 4155.55 | R7: 10 | S7: 0.1 | T7: 488.46
A8: ORD-10007 | B8: 46018 | C8: 46022 | D8: =TRIM('data cleaning'!$E8) -> Barbara Mora | E8: Barbara Mora | F8: =TRIM('data cleaning'!$G8) -> Corporate | G8: Corporate | H8: =TRIM('data cleaning'!$I8) -> East | I8: East | J8: =TRIM('data cleaning'!$K8) -> Furniture | K8: Furniture | L8: =TRIM('data cleaning'!$M8) -> Bookcases | M8: Bookcases | N8: =PROPER('data cleaning'!$O8) -> Available Bookcases | O8: =TRIM('data cleaning'!$P8) -> Available Bookcases | P8: Available Bookcases | Q8: 3876.69 | R8: 2 | S8: 0.05 | T8: 1072.16
A9: ORD-10008 | B9: 45288 | C9: 45294 | D9: =TRIM('data cleaning'!$E9) -> Gloria Brown | E9: Gloria Brown | F9: =TRIM('data cleaning'!$G9) -> Home Office | G9: Home Office | H9: =TRIM('data cleaning'!$I9) -> North | I9: North | J9: =TRIM('data cleaning'!$K9) -> Technology | K9: Technology | L9: =TRIM('data cleaning'!$M9) -> Laptops | M9: Laptops | N9: =PROPER('data cleaning'!$O9) -> Beautiful Laptops | O9: =TRIM('data cleaning'!$P9) -> Beautiful Laptops | P9: Beautiful Laptops | Q9: 855.14 | R9: 6 | S9: 0.05 | T9: 144.17
A10: ORD-10009 | B10: 45374 | C10: 45377 | D10: =TRIM('data cleaning'!$E10) -> Stephen Adkins | E10: Stephen Adkins | F10: =TRIM('data cleaning'!$G10) -> Corporate | G10: Corporate | H10: =TRIM('data cleaning'!$I10) -> South | I10: South | J10: =TRIM('data cleaning'!$K10) -> Office Supplies | K10: Office Supplies | L10: =TRIM('data cleaning'!$M10) -> Storage | M10: Storage | N10: =PROPER('data cleaning'!$O10) -> Purpose Storage | O10: =TRIM('data cleaning'!$P10) -> Purpose Storage | P10: Purpose Storage | Q10: 2693.99 | R10: 4 | S10: 0.05 | T10: 146.13
A11: ORD-10010 | B11: 46080 | C11: 46081 | D11: =TRIM('data cleaning'!$E11) -> Rachel Mathews | E11: Rachel Mathews | F11: =TRIM('data cleaning'!$G11) -> Consumer | G11: Consumer | H11: =TRIM('data cleaning'!$I11) -> South | I11: South | J11: =TRIM('data cleaning'!$K11) -> Office Supplies | K11: Office Supplies | L11: =TRIM('data cleaning'!$M11) -> Paper | M11: Paper | N11: =PROPER('data cleaning'!$O11) -> Last Paper | O11: =TRIM('data cleaning'!$P11) -> Last Paper | P11: Last Paper | Q11: 1183.79 | R11: 1 | S11: 0.1 | T11: 24.43
A12: ORD-10011 | B12: 45524 | C12: 45530 | D12: =TRIM('data cleaning'!$E12) -> Jacqueline Johnson | E12: Jacqueline Johnson | F12: =TRIM('data cleaning'!$G12) -> Home Office | G12: Home Office | H12: =TRIM('data cleaning'!$I12) -> West | I12: West | J12: =TRIM('data cleaning'!$K12) -> Office Supplies | K12: Office Supplies | L12: =TRIM('data cleaning'!$M12) -> Storage | M12: Storage | N12: =PROPER('data cleaning'!$O12) -> Prepare Storage | O12: =TRIM('data cleaning'!$P12) -> Prepare Storage | P12: Prepare Storage | Q12: 1102.5 | R12: 8 | S12: 0.15 | T12: 315.95
A13: ORD-10012 | B13: 45574 | C13: 45577 | D13: =TRIM('data cleaning'!$E13) -> Kevin Anderson | E13: Kevin Anderson | F13: =TRIM('data cleaning'!$G13) -> Home Office | G13: Home Office | H13: =TRIM('data cleaning'!$I13) -> West | I13: West | J13: =TRIM('data cleaning'!$K13) -> Furniture | K13: Furniture | L13: =TRIM('data cleaning'!$M13) -> Tables | M13: Tables | N13: =PROPER('data cleaning'!$O13) -> Live Tables | O13: =TRIM('data cleaning'!$P13) -> Live Tables | P13: Live Tables | Q13: 1270.81 | R13: 9 | S13: 0.2 | T13: -70.52
A14: ORD-10013 | B14: 45524 | C14: 45530 | D14: =TRIM('data cleaning'!$E14) -> Kenneth Sullivan | E14: Kenneth Sullivan | F14: =TRIM('data cleaning'!$G14) -> Consumer | G14: Consumer | H14: =TRIM('data cleaning'!$I14) -> North | I14: North | J14: =TRIM('data cleaning'!$K14) -> Office Supplies | K14: Office Supplies | L14: =TRIM('data cleaning'!$M14) -> Paper | M14: Paper | N14: =PROPER('data cleaning'!$O14) -> Example Paper | O14: =TRIM('data cleaning'!$P14) -> Example Paper | P14: Example Paper | Q14: 1135.64 | R14: 3 | S14: 0.2 | T14: 81.12
A15: ORD-10014 | B15: 45338 | C15: 45341 | D15: =TRIM('data cleaning'!$E15) -> John Bates | E15: John Bates | F15: =TRIM('data cleaning'!$G15) -> Corporate | G15: Corporate | H15: =TRIM('data cleaning'!$I15) -> West | I15: West | J15: =TRIM('data cleaning'!$K15) -> Furniture | K15: Furniture | L15: =TRIM('data cleaning'!$M15) -> Bookcases | M15: Bookcases | N15: =PROPER('data cleaning'!$O15) -> Individual Bookcases | O15: =TRIM('data cleaning'!$P15) -> Individual Bookcases | P15: Individual Bookcases | Q15: 3970.79 | R15: 7 | S15: 0.2 | T15: -655.42
A16: ORD-10015 | B16: 45214 | C16: 45223 | D16: =TRIM('data cleaning'!$E16) -> Patrick Horn | E16: Patrick Horn | F16: =TRIM('data cleaning'!$G16) -> Home Office | G16: Home Office | H16: =TRIM('data cleaning'!$I16) -> East | I16: East | J16: =TRIM('data cleaning'!$K16) -> Office Supplies | K16: Office Supplies | L16: =TRIM('data cleaning'!$M16) -> Paper | M16: Paper | N16: =PROPER('data cleaning'!$O16) -> Tough Paper | O16: =TRIM('data cleaning'!$P16) -> Tough Paper | P16: Tough Paper | Q16: 4310.86 | R16: 1 | T16: 846.64
A17: ORD-10016 | B17: 45297 | C17: 45299 | D17: =TRIM('data cleaning'!$E17) -> Danny Clark | E17: Danny Clark | F17: =TRIM('data cleaning'!$G17) -> Home Office | G17: Home Office | H17: =TRIM('data cleaning'!$I17) -> East | I17: East | J17: =TRIM('data cleaning'!$K17) -> Office Supplies | K17: Office Supplies | L17: =TRIM('data cleaning'!$M17) -> Paper | M17: Paper | N17: =PROPER('data cleaning'!$O17) -> Cover Paper | O17: =TRIM('data cleaning'!$P17) -> Cover Paper | P17: Cover Paper | Q17: 1502.83 | R17: 3 | S17: 0.15 | T17: -297.88
A18: ORD-10017 | B18: 45233 | C18: 45242 | D18: =TRIM('data cleaning'!$E18) -> Thomas Olson | E18: Thomas Olson | F18: =TRIM('data cleaning'!$G18) -> Consumer | G18: Consumer | H18: =TRIM('data cleaning'!$I18) -> South | I18: South | J18: =TRIM('data cleaning'!$K18) -> Office Supplies | K18: Office Supplies | L18: =TRIM('data cleaning'!$M18) -> Binders | M18: Binders | N18: =PROPER('data cleaning'!$O18) -> Thousand Binders | O18: =TRIM('data cleaning'!$P18) -> Thousand Binders | P18: Thousand Binders | Q18: 4567.51 | R18: 5 | T18: 361.81
A19: ORD-10018 | B19: 45669 | C19: 45678 | D19: =TRIM('data cleaning'!$E19) -> Jeffrey Levy | E19: Jeffrey Levy | F19: =TRIM('data cleaning'!$G19) -> Corporate | G19: Corporate | H19: =TRIM('data cleaning'!$I19) -> North | I19: North | J19: =TRIM('data cleaning'!$K19) -> Technology | K19: Technology | L19: =TRIM('data cleaning'!$M19) -> Phones | M19: Phones | N19: =PROPER('data cleaning'!$O19) -> Ahead Phones | O19: =TRIM('data cleaning'!$P19) -> Ahead Phones | P19: Ahead Phones | Q19: 4769.82 | R19: 9 | S19: 0 | T19: 617.31
A20: ORD-10019 | B20: 45262 | C20: 45267 | D20: =TRIM('data cleaning'!$E20) -> James Hamilton | E20: James Hamilton | F20: =TRIM('data cleaning'!$G20) -> Consumer | G20: Consumer | H20: =TRIM('data cleaning'!$I20) -> West | I20: West | J20: =TRIM('data cleaning'!$K20) -> Furniture | K20: Furniture | L20: =TRIM('data cleaning'!$M20) -> Tables | M20: Tables | N20: =PROPER('data cleaning'!$O20) -> Build Tables | O20: =TRIM('data cleaning'!$P20) -> Build Tables | P20: Build Tables | Q20: 1235.29 | R20: 4 | S20: 0.2 | T20: 396.31
A21: ORD-10020 | B21: 45662 | C21: 45665 | D21: =TRIM('data cleaning'!$E21) -> Joshua Smith | E21: Joshua Smith | F21: =TRIM('data cleaning'!$G21) -> Home Office | G21: Home Office | H21: =TRIM('data cleaning'!$I21) -> West | I21: West | J21: =TRIM('data cleaning'!$K21) -> Furniture | K21: Furniture | L21: =TRIM('data cleaning'!$M21) -> Bookcases | M21: Bookcases | N21: =PROPER('data cleaning'!$O21) -> Cell Bookcases | O21: =TRIM('data cleaning'!$P21) -> Cell Bookcases | P21: Cell Bookcases | Q21: 685.54 | R21: 8 | S21: 0.2 | T21: -74.85
A22: ORD-10021 | B22: 46154 | C22: 46158 | D22: =TRIM('data cleaning'!$E22) -> Lorraine Ruiz | E22: Lorraine Ruiz | F22: =TRIM('data cleaning'!$G22) -> Corporate | G22: Corporate | H22: =TRIM('data cleaning'!$I22) -> West | I22: West | J22: =TRIM('data cleaning'!$K22) -> Furniture | K22: Furniture | L22: =TRIM('data cleaning'!$M22) -> Bookcases | M22: Bookcases | N22: =PROPER('data cleaning'!$O22) -> Suddenly Bookcases | O22: =TRIM('data cleaning'!$P22) -> Suddenly Bookcases | P22: Suddenly Bookcases | Q22: 3579.1 | R22: 7 | T22: 563.47
A23: ORD-10022 | B23: 45989 | C23: 45993 | D23: =TRIM('data cleaning'!$E23) -> Terri Miller | E23: Terri Miller | F23: =TRIM('data cleaning'!$G23) -> Home Office | G23: Home Office | H23: =TRIM('data cleaning'!$I23) -> South | I23: South | J23: =TRIM('data cleaning'!$K23) -> Furniture | K23: Furniture | L23: =TRIM('data cleaning'!$M23) -> Chairs | M23: Chairs | N23: =PROPER('data cleaning'!$O23) -> Forget Chairs | O23: =TRIM('data cleaning'!$P23) -> Forget Chairs | P23: Forget Chairs | Q23: 366.93 | R23: 1 | S23: 0.2 | T23: 38.4
A24: ORD-10023 | B24: 45383 | C24: 45384 | D24: =TRIM('data cleaning'!$E24) -> Stacey Lewis | E24: Stacey Lewis | F24: =TRIM('data cleaning'!$G24) -> Consumer | G24: Consumer | H24: =TRIM('data cleaning'!$I24) -> East | I24: East | J24: =TRIM('data cleaning'!$K24) -> Furniture | K24: Furniture | L24: =TRIM('data cleaning'!$M24) -> Chairs | M24: Chairs | N24: =PROPER('data cleaning'!$O24) -> Than Chairs | O24: =TRIM('data cleaning'!$P24) -> Than Chairs | P24: Than Chairs | Q24: 1183.26 | R24: 1 | S24: 0.1 | T24: -190.54
A25: ORD-10024 | B25: 45796 | C25: 45800 | D25: =TRIM('data cleaning'!$E25) -> Amanda Roberts | E25: Amanda Roberts | F25: =TRIM('data cleaning'!$G25) -> Corporate | G25: Corporate | H25: =TRIM('data cleaning'!$I25) -> West | I25: West | J25: =TRIM('data cleaning'!$K25) -> Office Supplies | K25: Office Supplies | L25: =TRIM('data cleaning'!$M25) -> Paper | M25: Paper | N25: =PROPER('data cleaning'!$O25) -> Culture Paper | O25: =TRIM('data cleaning'!$P25) -> Culture Paper | P25: Culture Paper | Q25: 2719.21 | R25: 10 | S25: 0.2 | T25: 163.07
A26: ORD-10025 | B26: 45564 | C26: 45566 | D26: =TRIM('data cleaning'!$E26) -> William Fernandez | E26: William Fernandez | F26: =TRIM('data cleaning'!$G26) -> Home Office | G26: Home Office | H26: =TRIM('data cleaning'!$I26) -> North | I26: North | J26: =TRIM('data cleaning'!$K26) -> Furniture | K26: Furniture | L26: =TRIM('data cleaning'!$M26) -> Chairs | M26: Chairs | N26: =PROPER('data cleaning'!$O26) -> Cultural Chairs | O26: =TRIM('data cleaning'!$P26) -> Cultural Chairs | P26: Cultural Chairs | Q26: 3311.96 | R26: 6 | S26: 0.15 | T26: 86.46
A27: ORD-10026 | B27: 45647 | C27: 45649 | D27: =TRIM('data cleaning'!$E27) -> Nicholas Taylor | E27: Nicholas Taylor | F27: =TRIM('data cleaning'!$G27) -> Consumer | G27: Consumer | H27: =TRIM('data cleaning'!$I27) -> West | I27: West | J27: =TRIM('data cleaning'!$K27) -> Office Supplies | K27: Office Supplies | L27: =TRIM('data cleaning'!$M27) -> Storage | M27: Storage | N27: =PROPER('data cleaning'!$O27) -> Make Storage | O27: =TRIM('data cleaning'!$P27) -> Make Storage | P27: Make Storage | Q27: 350.03 | R27: 6 | S27: 0 | T27: -22.14
A28: ORD-10027 | B28: 45441 | C28: 45444 | D28: =TRIM('data cleaning'!$E28) -> Amanda Roy | E28: Amanda Roy | F28: =TRIM('data cleaning'!$G28) -> Home Office | G28: Home Office | H28: =TRIM('data cleaning'!$I28) -> North | I28: North | J28: =TRIM('data cleaning'!$K28) -> Furniture | K28: Furniture | L28: =TRIM('data cleaning'!$M28) -> Tables | M28: Tables | N28: =PROPER('data cleaning'!$O28) -> His Tables | O28: =TRIM('data cleaning'!$P28) -> His Tables | P28: His Tables | Q28: 1428.8 | R28: 4 | S28: 0 | T28: 62.47
A29: ORD-10028 | B29: 45683 | C29: 45692 | D29: =TRIM('data cleaning'!$E29) -> Charles Moore | E29: Charles Moore | F29: =TRIM('data cleaning'!$G29) -> Corporate | G29: Corporate | H29: =TRIM('data cleaning'!$I29) -> West | I29: West | J29: =TRIM('data cleaning'!$K29) -> Furniture | K29: Furniture | L29: =TRIM('data cleaning'!$M29) -> Bookcases | M29: Bookcases | N29: =PROPER('data cleaning'!$O29) -> Yeah Bookcases | O29: =TRIM('data cleaning'!$P29) -> Yeah Bookcases | P29: Yeah Bookcases | Q29: 4188.34 | R29: 2 | S29: 0.05 | T29: -454.56
A30: ORD-10029 | B30: 45352 | C30: 45353 | D30: =TRIM('data cleaning'!$E30) -> Linda Wells | E30: Linda Wells | F30: =TRIM('data cleaning'!$G30) -> Corporate | G30: Corporate | H30: =TRIM('data cleaning'!$I30) -> East | I30: East | J30: =TRIM('data cleaning'!$K30) -> Furniture | K30: Furniture | L30: =TRIM('data cleaning'!$M30) -> Tables | M30: Tables | N30: =PROPER('data cleaning'!$O30) -> Important Tables | O30: =TRIM('data cleaning'!$P30) -> Important Tables | P30: Important Tables | Q30: 864.95 | R30: 1 | S30: 0.15 | T30: -46.83
A31: ORD-10030 | B31: 45088 | C31: 45097 | D31: =TRIM('data cleaning'!$E31) -> Daniel King | E31: Daniel King | F31: =TRIM('data cleaning'!$G31) -> Consumer | G31: Consumer | H31: =TRIM('data cleaning'!$I31) -> North | I31: North | J31: =TRIM('data cleaning'!$K31) -> Technology | K31: Technology | L31: =TRIM('data cleaning'!$M31) -> Laptops | M31: Laptops | N31: =PROPER('data cleaning'!$O31) -> Themselves Laptops | O31: =TRIM('data cleaning'!$P31) -> Themselves Laptops | P31: Themselves Laptops | Q31: 3326.26 | R31: 8 | S31: 0.05 | T31: -317.84
A32: ORD-10031 | B32: 46145 | C32: 46154 | D32: =TRIM('data cleaning'!$E32) -> Ricardo Ramirez | E32: Ricardo Ramirez | F32: =TRIM('data cleaning'!$G32) -> Corporate | G32: Corporate | H32: =TRIM('data cleaning'!$I32) -> South | I32: South | J32: =TRIM('data cleaning'!$K32) -> Office Supplies | K32: Office Supplies | L32: =TRIM('data cleaning'!$M32) -> Storage | M32: Storage | N32: =PROPER('data cleaning'!$O32) -> Growth Storage | O32: =TRIM('data cleaning'!$P32) -> Growth Storage | P32: Growth Storage | Q32: 351.74 | R32: 6 | S32: 0 | T32: -60.65
A33: ORD-10032 | B33: 45961 | C33: 45963 | D33: =TRIM('data cleaning'!$E33) -> Erika Ellis | E33: Erika Ellis | F33: =TRIM('data cleaning'!$G33) -> Consumer | G33: Consumer | H33: =TRIM('data cleaning'!$I33) -> West | I33: West | J33: =TRIM('data cleaning'!$K33) -> Furniture | K33: Furniture | L33: =TRIM('data cleaning'!$M33) -> Bookcases | M33: Bookcases | N33: =PROPER('data cleaning'!$O33) -> One Bookcases | O33: =TRIM('data cleaning'!$P33) -> One Bookcases | P33: One Bookcases | Q33: 4264.15 | R33: 2 | S33: 0.2 | T33: -693.44
A34: ORD-10033 | B34: 46008 | C34: 46012 | D34: =TRIM('data cleaning'!$E34) -> Pamela Norman | E34: Pamela Norman | F34: =TRIM('data cleaning'!$G34) -> Home Office | G34: Home Office | H34: =TRIM('data cleaning'!$I34) -> East | I34: East | J34: =TRIM('data cleaning'!$K34) -> Furniture | K34: Furniture | L34: =TRIM('data cleaning'!$M34) -> Bookcases | M34: Bookcases | N34: =PROPER('data cleaning'!$O34) -> Wait Bookcases | O34: =TRIM('data cleaning'!$P34) -> Wait Bookcases | P34: Wait Bookcases | Q34: 2915.65 | R34: 1 | S34: 0.2 | T34: -451.66
... A37: ORD-10036 | B37: 45724 | C37: 45726 | D37: =TRIM('data cleaning'!$E37) -> Katelyn Williams | E37: Katelyn Williams | F37: =TRIM('data cleaning'!$G37) -> Home Office | G37: Home Office | H37: =TRIM('data cleaning'!$I37) -> East | I37: East | J37: =TRIM('data cleaning'!$K37) -> Furniture | K37: Furniture | L37: =TRIM('data cleaning'!$M37) -> Tables | M37: Tables | N37: =PROPER('data cleaning'!$O37) -> Son Tables | O37: =TRIM('data cleaning'!$P37) -> Son Tables | P37: Son Tables | Q37: 4402.39 | R37: 6 | S37: 0.1 | T37: -498.52
A38: ORD-10037 | B38: 07-11-2023 | C38: 45246 | D38: =TRIM('data cleaning'!$E38) -> Shannon Wagner | E38: Shannon Wagner | F38: =TRIM('data cleaning'!$G38) -> Consumer | G38: Consumer | H38: =TRIM('data cleaning'!$I38) -> South | I38: South | J38: =TRIM('data cleaning'!$K38) -> Office Supplies | K38: Office Supplies | L38: =TRIM('data cleaning'!$M38) -> Storage | M38: Storage | N38: =PROPER('data cleaning'!$O38) -> With Storage | O38: =TRIM('data cleaning'!$P38) -> With Storage | P38: With Storage | Q38: 88.72 | R38: 9 | S38: 0.1 | T38: 27.72
A39: ORD-10038 | B39: 45815 | C39: 45817 | D39: =TRIM('data cleaning'!$E39) -> Kelli Johnson | E39: Kelli Johnson | F39: =TRIM('data cleaning'!$G39) -> Consumer | G39: Consumer | H39: =TRIM('data cleaning'!$I39) -> East | I39: East | J39: =TRIM('data cleaning'!$K39) -> Technology | K39: Technology | L39: =TRIM('data cleaning'!$M39) -> Phones | M39: Phones | N39: =PROPER('data cleaning'!$O39) -> This Phones | O39: =TRIM('data cleaning'!$P39) -> This Phones | P39: This Phones | Q39: 3724.96 | R39: 3 | S39: 0.1 | T39: -167.75
A40: ORD-10039 | B40: 45087 | C40: 45092 | D40: =TRIM('data cleaning'!$E40) -> Rebecca Blake | E40: Rebecca Blake | F40: =TRIM('data cleaning'!$G40) -> Corporate | G40: Corporate | H40: =TRIM('data cleaning'!$I40) -> East | I40: East | J40: =TRIM('data cleaning'!$K40) -> Furniture | K40: Furniture | L40: =TRIM('data cleaning'!$M40) -> Bookcases | M40: Bookcases | N40: =PROPER('data cleaning'!$O40) -> Throughout Bookcases | O40: =TRIM('data cleaning'!$P40) -> Throughout Bookcases | P40: Throughout Bookcases | Q40: 2551.77 | R40: 5 | S40: 0 | T40: -380.82
A41: ORD-10040 | B41: 46089 | C41: 46095 | D41: =TRIM('data cleaning'!$E41) -> Brian Gallagher | E41: Brian Gallagher | F41: =TRIM('data cleaning'!$G41) -> Home Office | G41: Home Office | H41: =TRIM('data cleaning'!$I41) -> West | I41: West | J41: =TRIM('data cleaning'!$K41) -> Furniture | K41: Furniture | L41: =TRIM('data cleaning'!$M41) -> Chairs | M41: Chairs | N41: =PROPER('data cleaning'!$O41) -> According Chairs | O41: =TRIM('data cleaning'!$P41) -> According Chairs | P41: According Chairs | Q41: 3867.04 | R41: 5 | S41: 0.05 | T41: 803.1
A42: ORD-10041 | B42: 45846 | C42: 45848 | D42: =TRIM('data cleaning'!$E42) -> Melissa Burgess | E42: Melissa Burgess | F42: =TRIM('data cleaning'!$G42) -> Corporate | G42: Corporate | H42: =TRIM('data cleaning'!$I42) -> South | I42: South | J42: =TRIM('data cleaning'!$K42) -> Office Supplies | K42: Office Supplies | L42: =TRIM('data cleaning'!$M42) -> Binders | M42: Binders | N42: =PROPER('data cleaning'!$O42) -> Three Binders | O42: =TRIM('data cleaning'!$P42) -> Three Binders | P42: Three Binders | Q42: 422.46 | R42: 3 | S42: 0.2 | T42: -76.12
...

Sheet cleaned data
A1: Order ID | B1: Order Date | C1: Ship Date | D1: Customer Name | E1: Segment | F1: Region | G1: Category | H1: Sub-Category | I1: Product Name | J1: Sales | K1: Quantity | L1: Discount | M1: Profit | N1: Profit Status
A2: ORD-10327 | B2: 45073 | C2: 45075 | D2: Michael Li | E2: Consumer | F2: West | G2: Furniture | H2: Tables | I2: While Tables | J2: 2907.87 | K2: 9 | L2: 0.05 | M2: 3.45 | N2: =IF(Table3[[#This Row],[Profit]]<0,"Loss","Profit") -> Profit
A3: ORD-10075 | B3: 45071 | C3: 45077 | D3: Nicholas Fischer Iii | E3: Corporate | F3: North | G3: Office Supplies | H3: Binders | I3: Whose Binders | J3: 2687.09 | K3: 6 | L3: 0 | M3: 210.34 | N3: =IF(Table3[[#This Row],[Profit]]<0,"Loss","Profit") -> Profit
A4: ORD-10590 | B4: 45074 | C4: 45080 | D4: Jeremy Norris | E4: Home Office | F4: East | G4: Furniture | H4: Bookcases | I4: Explain Bookcases | J4: 4308.83 | K4: 6 | L4: 0.15 | M4: 245.42 | N4: =IF(Table3[[#This Row],[Profit]]<0,"Loss","Profit") -> Profit
A5: ORD-10603 | B5: 45079 | C5: 45080 | D5: Tina Santos | E5: Corporate | F5: South | G5: Technology | H5: Accessories | I5: Consumer Accessories | J5: 653.71 | K5: 4 | L5: 0.15 | M5: 146.54 | N5: =IF(Table3[[#This Row],[Profit]]<0,"Loss","Profit") -> Profit
A6: ORD-10486 | B6: 45073 | C6: 45083 | D6: Rachel Santos | E6: Home Office | F6: North | G6: Technology | H6: Accessories | I6: Face Accessories | J6: 4783.14 | K6: 3 | L6: 0.15 | M6: -945.22 | N6: =IF(Table3[[#This Row],[Profit]]<0,"Loss","Profit") -> Loss
A7: ORD-10233 | B7: 45080 | C7: 45083 | D7: Margaret English | E7: Home Office | F7: East | G7: Office Supplies | H7: Paper | I7: Unit Paper | J7: 3050.99 | K7: 9 | L7: 0.05 | M7: -59.86 | N7: =IF(Table3[[#This Row],[Profit]]<0,"Loss","Profit") -> Loss
A8: ORD-10073 | B8: 45081 | C8: 45083 | D8: Patricia Rojas | E8: Corporate | F8: West | G8: Furniture | H8: Tables | I8: Despite Tables | J8: 2914.49 | K8: 5 | L8: 0.2 | M8: 502.87 | N8: =IF(Table3[[#This Row],[Profit]]<0,"Loss","Profit") -> Profit
A9: ORD-10261 | B9: 45084 | C9: 45086 | D9: Melissa Murphy | E9: Home Office | F9: South | G9: Furniture | H9: Bookcases | I9: Generation Bookcases | J9: 355.7 | K9: 9 | L9: 0.2 | M9: -31.59 | N9: =IF(Table3[[#This Row],[Profit]]<0,"Loss","Profit") -> Loss
A10: ORD-10595 | B10: 45087 | C10: 45088 | D10: Felicia Jones | E10: Corporate | F10: West | G10: Office Supplies | H10: Binders | I10: Quite Binders | J10: 2763.65 | K10: 4 | L10: 0.15 | M10: 788.16 | N10: =IF(Table3[[#This Row],[Profit]]<0,"Loss","Profit") -> Profit
A11: ORD-10288 | B11: 45088 | C11: 45089 | D11: Nicholas Castro | E11: Consumer | F11: West | G11: Furniture | H11: Bookcases | I11: Travel Bookcases | J11: 2643.52 | K11: 2 | L11: 0.2 | M11: -458.17 | N11: =IF(Table3[[#This Row],[Profit]]<0,"Loss","Profit") -> Loss
A12: ORD-10143 | B12: 45083 | C12: 45092 | D12: Sharon Scott | E12: Corporate | F12: West | G12: Office Supplies | H12: Binders | I12: Goal Binders | J12: 1543.07 | K12: 1 | L12: 0 | M12: 538.88 | N12: =IF(Table3[[#This Row],[Profit]]<0,"Loss","Profit") -> Profit
A13: ORD-10682 | B13: 45085 | C13: 45092 | D13: David Logan | E13: Home Office | F13: North | G13: Technology | H13: Laptops | I13: Yourself Laptops | J13: 2647 | K13: 4 | L13: 0.2 | M13: -444.69 | N13: =IF(Table3[[#This Row],[Profit]]<0,"Loss","Profit") -> Loss
... A73: ORD-10369 | B73: 45183 | C73: 45185 | D73: Elizabeth Park | E73: Consumer | F73: South | G73: Furniture | H73: Bookcases | I73: Thank Bookcases | J73: 1180.6 | K73: 9 | L73: 0 | M73: -207.52 | N73: =IF(Table3[[#This Row],[Profit]]<0,"Loss","Profit") -> Loss
A74: ORD-10187 | B74: 15-09-2023 | C74: 45185 | D74: Phyllis Arnold | E74: Consumer | F74: South | G74: Technology | H74: Phones | I74: Not Phones | J74: 1627.49 | K74: 2 | L74: 0.2 | M74: 256.29 | N74: =IF(Table3[[#This Row],[Profit]]<0,"Loss","Profit") -> Profit
A75: ORD-10222 | B75: 45184 | C75: 45188 | D75: Tiffany Young | E75: Corporate | F75: East | G75: Technology | H75: Accessories | I75: Specific Accessories | J75: 1733.95 | K75: 3 | L75: 0.1 | M75: 474.78 | N75: =IF(Table3[[#This Row],[Profit]]<0,"Loss","Profit") -> Profit
A76: ORD-10414 | B76: 45184 | C76: 45189 | D76: Kyle Sandoval | E76: Corporate | F76: South | G76: Office Supplies | H76: Paper | I76: Example Paper | J76: 1225.86 | K76: 1 | L76: 0.15 | M76: 140.33 | N76: =IF(Table3[[#This Row],[Profit]]<0,"Loss","Profit") -> Profit
A77: ORD-10287 | B77: 45182 | C77: 45190 | D77: Amanda Jones | E77: Home Office | F77: West | G77: Technology | H77: Accessories | I77: Skill Accessories | J77: 2331.1 | K77: 6 | L77: 0.05 | M77: -286.78 | N77: =IF(Table3[[#This Row],[Profit]]<0,"Loss","Profit") -> Loss
A78: ORD-10332 | B78: 45184 | C78: 45192 | D78: Danielle Morgan | E78: Home Office | F78: North | G78: Office Supplies | H78: Binders | I78: Difference Binders | J78: 1479.73 | K78: 3 | L78: 0.1 | M78: 389.3 | N78: =IF(Table3[[#This Row],[Profit]]<0,"Loss","Profit") -> Profit
A79: ORD-10062 | B79: 45190 | C79: 45192 | D79: John Potts | E79: Home Office | F79: South | G79: Technology | H79: Laptops | I79: Shake Laptops | J79: 734.95 | K79: 4 | L79: 0.15 | M79: 133.52 | N79: =IF(Table3[[#This Row],[Profit]]<0,"Loss","Profit") -> Profit
A80: ORD-10270 | B80: 45191 | C80: 45193 | D80: Robert Benitez | E80: Consumer | F80: South | G80: Technology | H80: Phones | I80: Environmental Phones | J80: 209.48 | K80: 7 | L80: 0.2 | M80: 46.36 | N80: =IF(Table3[[#This Row],[Profit]]<0,"Loss","Profit") -> Profit
A81: ORD-10077 | B81: 17-09-2023 | C81: 45195 | D81: William Gonzalez | E81: Home Office | F81: West | G81: Technology | H81: Phones | I81: Type Phones | J81: 4829.09 | K81: 5 | L81: 0.2 | M81: 1180.76 | N81: =IF(Table3[[#This Row],[Profit]]<0,"Loss","Profit") -> Profit
A82: ORD-10359 | B82: 45191 | C82: 45197 | D82: Joshua Costa | E82: Home Office | F82: West | G82: Office Supplies | H82: Binders | I82: End Binders | J82: 4672.93 | K82: 3 | L82: 0.15 | M82: 1277.8 | N82: =IF(Table3[[#This Row],[Profit]]<0,"Loss","Profit") -> Profit
A83: ORD-10251 | B83: 45194 | C83: 45199 | D83: Unknown | E83: Home Office | F83: West | G83: Furniture | H83: Chairs | I83: Marriage Chairs | J83: 2861.41 | K83: 2 | L83: 0.1 | M83: -124.45 | N83: =IF(Table3[[#This Row],[Profit]]<0,"Loss","Profit") -> Loss
A84: ORD-10601 | B84: 45195 | C84: 45200 | D84: Andrea Sandoval | E84: Consumer | F84: East | G84: Technology | H84: Accessories | I84: Rock Accessories | J84: 3939.34 | K84: 8 | L84: 0.1 | M84: 216.77 | N84: =IF(Table3[[#This Row],[Profit]]<0,"Loss","Profit") -> Profit
A85: ORD-10156 | B85: 45191 | C85: 45201 | D85: Unknown | E85: Home Office | F85: North | G85: Office Supplies | H85: Paper | I85: Able Paper | J85: 3001.31 | K85: 1 | L85: 0.05 | M85: -340.42 | N85: =IF(Table3[[#This Row],[Profit]]<0,"Loss","Profit") -> Loss
A86: ORD-10354 | B86: 45192 | C86: 45202 | D86: Christopher Kim | E86: Consumer | F86: West | G86: Furniture | H86: Bookcases | I86: Agency Bookcases | J86: 91.95 | K86: 3 | L86: 0.15 | M86: -0.63 | N86: =IF(Table3[[#This Row],[Profit]]<0,"Loss","Profit") -> Loss
A87: ORD-10182 | B87: 45198 | C87: 45202 | D87: Justin Jones | E87: Home Office | F87: West | G87: Furniture | H87: Bookcases | I87: Best Bookcases | J87: 1581.87 | K87: 8 | L87: 0.05 | M87: 3.66 | N87: =IF(Table3[[#This Row],[Profit]]<0,"Loss","Profit") -> Profit
A88: ORD-10223 | B88: 45197 | C88: 45203 | D88: Scott Miller | E88: Consumer | F88: East | G88: Technology | H88: Phones | I88: Until Phones | J88: 2599.15 | K88: 2 | L88: 0.1 | M88: -174.26 | N88: =IF(Table3[[#This Row],[Profit]]<0,"Loss","Profit") -> Loss
A89: ORD-10509 | B89: 45195 | C89: 45204 | D89: Stephanie Howard | E89: Consumer | F89: South | G89: Furniture | H89: Chairs | I89: Fight Chairs | J89: 4152.31 | K89: 7 | L89: 0.2 | M89: 1034.82 | N89: =IF(Table3[[#This Row],[Profit]]<0,"Loss","Profit") -> Profit
A90: ORD-10429 | B90: 45199 | C90: 45204 | D90: Michelle Hudson | E90: Consumer | F90: South | G90: Furniture | H90: Tables | I90: Still Tables | J90: 1589.2 | K90: 8 | L90: 0.2 | M90: 280.76 | N90: =IF(Table3[[#This Row],[Profit]]<0,"Loss","Profit") -> Profit
A91: ORD-10560 | B91: 45201 | C91: 45206 | D91: Thomas Nash | E91: Corporate | F91: South | G91: Furniture | H91: Bookcases | I91: Later Bookcases | J91: 3644.39 | K91: 9 | L91: 0.2 | M91: -31.15 | N91: =IF(Table3[[#This Row],[Profit]]<0,"Loss","Profit") -> Loss
A92: ORD-10614 | B92: 45201 | C92: 45206 | D92: Michael Blake | E92: Home Office | F92: West | G92: Technology | H92: Accessories | I92: Focus Accessories | J92: 2730.95 | K92: 8 | L92: 0 | M92: 619.26 | N92: =IF(Table3[[#This Row],[Profit]]<0,"Loss","Profit") -> Profit
A93: ORD-10497 | B93: 45201 | C93: 45208 | D93: Anne Cooper | E93: Home Office | F93: East | G93: Technology | H93: Accessories | I93: Church Accessories | J93: 4785.67 | K93: 6 | L93: 0.2 | M93: -815.52 | N93: =IF(Table3[[#This Row],[Profit]]<0,"Loss","Profit") -> Loss
... A117: ORD-10272 | B117: 45239 | C117: 45246 | D117: Eric Taylor | E117: Consumer | F117: South | G117: Office Supplies | H117: Binders | I117: Three Binders | J117: 2222.87 | K117: 9 | L117: 0.05 | M117: 477.72 | N117: =IF(Table3[[#This Row],[Profit]]<0,"Loss","Profit") -> Profit
A118: ORD-10037 | B118: 07-11-2023 | C118: 45246 | D118: Shannon Wagner | E118: Consumer | F118: South | G118: Office Supplies | H118: Storage | I118: With Storage | J118: 88.72 | K118: 9 | L118: 0.1 | M118: 27.72 | N118: =IF(Table3[[#This Row],[Profit]]<0,"Loss","Profit") -> Profit
A119: ORD-10582 | B119: 08-11-2023 | C119: 45247 | D119: Daniel Bowman | E119: Corporate | F119: West | G119: Technology | H119: Laptops | I119: Career Laptops | J119: 2463.09 | K119: 8 | L119: 0 | M119: 23.62 | N119: =IF(Table3[[#This Row],[Profit]]<0,"Loss","Profit") -> Profit
A120: ORD-10248 | B120: 45249 | C120: 45252 | D120: Samantha Briggs | E120: Corporate | F120: West | G120: Furniture | H120: Bookcases | I120: Painting Bookcases | J120: 75.65 | K120: 9 | L120: 0.05 | M120: 1.8 | N120: =IF(Table3[[#This Row],[Profit]]<0,"Loss","Profit") -> Profit
A121: ORD-10328 | B121: 45245 | C121: 45253 | D121: Christopher Jones | E121: Corporate | F121: North | G121: Furniture | H121: Tables | I121: Marriage Tables | J121: 2662.19 | K121: 6 | L121: 0.2 | M121: 36.61 | N121: =IF(Table3[[#This Row],[Profit]]<0,"Loss","Profit") -> Profit
A122: ORD-10266 | B122: 45250 | C122: 45253 | D122: Marcus Smith | E122: Corporate | F122: West | G122: Technology | H122: Accessories | I122: Such Accessories | J122: 3856.41 | K122: 7 | L122: 0.1 | M122: 1334.59 | N122: =IF(Table3[[#This Row],[Profit]]<0,"Loss","Profit") -> Profit
...

Sheet pivot
A3: Row Labels | B3: Sum of Profit | D3: Row Labels | E3: Sum of Sales | G3: Row Labels | H3: Sum of Profit | J3: Row Labels | K3: Sum of Profit
A4: East | B4: 33519.38 | D4: East | E4: 503502.56 | G4: Consumer | H4: 38390.51 | J4: Furniture | K4: 52988.84
A5: North | B5: 25948.62 | D5: North | E5: 412491.76 | G5: Corporate | H5: 48388.25 | J5: Office Supplies | K5: 43084.21
A6: South | B6: 38760.63 | D6: South | E6: 433256.43 | G6: Home Office | H6: 53278.76 | J6: Technology | K6: 43984.47
A7: West | B7: 41828.89 | D7: West | E7: 531022.96 | G7: Grand Total | H7: 140057.52 | J7: Grand Total | K7: 140057.52
A8: Grand Total | B8: 140057.52 | D8: Grand Total | E8: 1880273.7
A11: Row Labels | B11: Count of Order ID | D11: Row Labels | E11: Sum of Sales | G11: Row Labels | H11: Sum of Profit
A12: East | B12: 192 | D12: Furniture | E12: 644115.56 | G12: East | H12: 33519.38
A13: North | B13: 166 | D13: Office Supplies | E13: 584271.08 | G13: Loss | H13: -18408.21
A14: South | B14: 182 | D14: Technology | E14: 651887.07 | G14: Profit | H14: 51927.59
A15: West | B15: 210 | D15: Grand Total | E15: 1880273.7 | G15: North | H15: 25948.62
A16: Grand Total | B16: 750 | G16: Loss | H16: -14358.46
G17: Profit | H17: 40307.08
G18: South | H18: 38760.63
G19: Loss | H19: -12181.6
G20: Profit | H20: 50942.23
G21: West | H21: 41828.89
G22: Loss | H22: -21336.52
G23: Profit | H23: 63165.41
G24: Grand Total | H24: 140057.52
